Workbook

Sheet 📊 Raw Dataset
A1: PIZZA SALES DATASET — MONTHLY REVENUE (2018–2025) | India Market
A2: Units: Revenue in ₹ (Thousands) | Includes COVID-19 Impact: 2020 Lockdown 1.0 & 2021 Second Wave (Delta) | 2022 Omicron partial impact
A3: 🔴 RED = Lockdown/Severely impacted months | 🟡 YELLOW = Partial unlock/recovery | 🟢 GREEN = Recovery to pre-COVID levels
A5: Year | B5: Jan | C5: Feb | D5: Mar | E5: Apr | F5: May | G5: Jun | H5: Jul | I5: Aug | J5: Sep | K5: Oct | L5: Nov | M5: Dec | N5: Annual Total
A6: 2018 | B6: 520 | C6: 480 | D6: 610 | E6: 590 | F6: 650 | G6: 720 | H6: 780 | I6: 810 | J6: 740 | K6: 680 | L6: 760 | M6: 920 | N6: =SUM(B6:M6) -> 8260
A7: 2019 | B7: 562 | C7: 518 | D7: 659 | E7: 637 | F7: 702 | G7: 778 | H7: 842 | I7: 875 | J7: 799 | K7: 734 | L7: 821 | M7: 994 | N7: =SUM(B7:M7) -> 8921
A8: 2020 | B8: 558 | C8: 510 | D8: 310 | E8: 95 | F8: 120 | G8: 195 | H8: 420 | I8: 455 | J8: 415 | K8: 478 | L8: 445 | M8: 520 | N8: =SUM(B8:M8) -> 4521
A9: 2021 | B9: 340 | C9: 320 | D9: 398 | E9: 110 | F9: 130 | G9: 260 | H9: 490 | I9: 530 | J9: 500 | K9: 580 | L9: 560 | M9: 710 | N9: =SUM(B9:M9) -> 4928
A10: 2022 | B10: 295 | C10: 350 | D10: 480 | E10: 560 | F10: 610 | G10: 660 | H10: 720 | I10: 760 | J10: 700 | K10: 730 | L10: 770 | M10: 910 | N10: =SUM(B10:M10) -> 7545
A11: 2023 | B11: 680 | C11: 630 | D11: 740 | E11: 770 | F11: 840 | G11: 910 | H11: 980 | I11: 1020 | J11: 940 | K11: 880 | L11: 970 | M11: 1150 | N11: =SUM(B11:M11) -> 10510
A12: 2024 | B12: 740 | C12: 690 | D12: 800 | E12: 840 | F12: 910 | G12: 990 | H12: 1060 | I12: 1110 | J12: 1020 | K12: 950 | L12: 1050 | M12: 1250 | N12: =SUM(B12:M12) -> 11410
A13: 2025 | B13: 800 | C13: 750 | D13: 870 | E13: 920 | F13: 995 | G13: 1080 | H13: 1150 | I13: 1200 | J13: 1100 | K13: 1030 | L13: 1130 | M13: 1350 | N13: =SUM(B13:M13) -> 12375
A14: 📌 KEY EVENTS: Mar 2020 — Janata Curfew & start of lockdown | Apr–May 2020 — National Lockdown 1.0 (dine-in = ₹0) | Apr–May 2021 — Delta Second Wave, state-level lockdowns | Jan 2022 — Omicron wave scare, reduced footfall | Mar 2022 onwards — Full unlock

Sheet 📝 Question Paper
A1: PIZZA SALES ANALYSIS — ASSESSMENT PAPER | India Market (2018–2025)
A2: Duration: 90 Minutes | Total Marks: 100 | Dataset: '📊 Raw Dataset' Sheet | All calculations MUST use Excel formulas — no hardcoded values
A3: CONTEXT: Data reflects real India market conditions — National Lockdown 1.0 (Apr–May 2020), Delta Second Wave (Apr–May 2021), and Omicron scare (Jan 2022). Factor these events into your analysis.
A5: PART A — QUANTITATIVE ANALYSIS (Excel Formulas Required) [60 Marks]
A6: Q1. | B6: Calculate the Month-on-Month (MoM) % change for every month from Feb 2018 to Dec 2025 using: ((Current – Previous) / Previous) × 100. Identify the single largest MoM drop and largest MoM recovery in the entire dataset. | J6: [8 Marks]
A7: Q2. | B7: Calculate Year-on-Year (YoY) Annual Growth Rate for each year (2019–2025) using Annual Totals. Clearly identify: (a) which years show NEGATIVE growth, (b) the best recovery year, and (c) the worst impacted year. | J7: [8 Marks]
A8: Q3. | B8: Compute the CAGR of pizza sales from 2018 to 2025 using: CAGR = (End Value / Start Value)^(1/n) – 1. Then separately compute the CAGR for the PRE-COVID period (2018–2019) and POST-COVID recovery period (2022–2025). Compare and interpret. | J8: [7 Marks]
A9: Q4. | B9: COVID DEPTH ANALYSIS: Compare Apr–May 2020 (Lockdown 1.0) vs Apr–May 2019 (normal). Calculate: (a) absolute sales drop, (b) % decline, (c) estimated revenue lost assuming 2019 levels had continued. | J9: [7 Marks]
A10: Q5. | B10: SECOND WAVE ANALYSIS: Compare Apr–May 2021 vs Apr–May 2020. Was the second wave worse or better than the first in sales terms? Calculate the % difference and give a reason for your finding. | J10: [6 Marks]
A11: Q6. | B11: Calculate the RECOVERY RATE: Define recovery as the year when Annual Total first exceeded 2019's Annual Total. Compute: (2019 Total – Lowest COVID Year Total) / 2019 Total × 100 to find the depth of trough, and the number of years taken to recover. | J11: [5 Marks]
A12: Q7. | B12: Calculate the monthly Seasonal Index for each of the 12 months (average of all 8 years / overall monthly average × 100). Note: COVID months WILL distort this — compute a 'cleaned' seasonal index EXCLUDING 2020 and 2021 data and compare both. | J12: [6 Marks]
A13: Q8. | B13: Compute the Standard Deviation (STDEV) of monthly sales for each year. Which year was most volatile? Explain WHY 2020 and 2021 have the highest standard deviation in the context of India's lockdown pattern. | J13: [5 Marks]
A14: Q9. | B14: Each year's share (%) of Total 8-Year Grand Sales: (Year Total / Grand Total) × 100. Identify which COVID years show a significantly lower share and what the combined revenue loss (vs projected growth) was. | J14: [5 Marks]
A15: Q10. | B15: 3-Month Moving Average: Calculate for the full timeline Jan 2018 – Dec 2025. Identify where the moving average shows the steepest decline (COVID) and the steepest sustained rise (post-COVID boom). | J15: [3 Marks]
A17: PART B — EXCEL SKILLS (Charts, Functions & Formatting) [25 Marks]
A18: Q11. | B18: LINE CHART — Annual Total Sales 2018–2025: Add title, axis labels, data labels. Highlight 2020 and 2021 bars/points in RED to show COVID impact years. Add an annotation arrow pointing to the 'V-shaped recovery' from 2022 onwards. | J18: [7 Marks]
A19: Q12. | B19: CLUSTERED BAR CHART — Compare H1 (Jan–Jun) vs H2 (Jul–Dec) sales for each year. This should visually show how H1 was devastated in 2020 and 2021 while H2 partially recovered each year. | J19: [6 Marks]
A20: Q13. | B20: CONDITIONAL FORMATTING on Raw Dataset: 🔴 Red fill = sales below 200 (severe lockdown), 🟡 Yellow = 200–500 (impacted), 🟢 Green = above 900 (healthy). Apply to all 96 monthly data cells. | J20: [5 Marks]
A21: Q14. | B21: SUMMARY TABLE using formulas (SUMIF / AVERAGEIF / MAX / MIN) for each year: Annual Total, Monthly Average, Best Month (value + name), Worst Month (value + name), Half-Year H1 vs H2 split. | J21: [7 Marks]
A23: PART C — QUALITATIVE ANALYSIS (Written in Answer Sheet) [15 Marks]
A24: Q15. | B24: TREND ANALYSIS (8–10 lines): Describe the overall sales trajectory 2018–2025. Mandatory references: (a) the exact Apr 2020 figure, (b) the YoY decline % in 2020, (c) which year sales first crossed 2019 levels again, and (d) the post-2022 growth rate. | J24: [5 Marks]
A25: Q16. | B25: BUSINESS STRATEGY REPORT (10–12 lines): As a consultant to a pizza chain owner in India, what 5 concrete recommendations would you make? Base each recommendation on specific data patterns from the dataset — seasonal, COVID impact, recovery speed. | J25: [6 Marks]
A26: Q17. | B26: RISK & OPPORTUNITY ASSESSMENT (6–8 lines): Identify 3 risks and 3 opportunities visible in the data, with specific reference to months, years, or % figures from the dataset. | J26: [4 Marks]

Sheet ✍ Answer Sheet
A1: MODEL ANSWER SHEET — PIZZA SALES QUANTITATIVE ANALYSIS (India, 2018–2025)
A2: All values via Excel formulas referencing '📊 Raw Dataset' | Green text = formula | Note: COVID distortion acknowledged in all COVID-era calculations
A4: Q2 — YEAR-ON-YEAR (YoY) GROWTH RATE WITH COVID CONTEXT
A5: Year | B5: Annual Total (₹K) | C5: YoY Change (₹K) | D5: YoY Growth % | E5: COVID Context / Remark
A6: 2018 | B6: ='📊 Raw Dataset'!N6 -> 8260 | C6: — | D6: Base Year | E6: ✅ Baseline Year
A7: 2019 | B7: ='📊 Raw Dataset'!N7 -> 8921 | C7: =B7-B6 -> 661 | D7: =(B7-B6)/B6 -> 0.080024213 | E7: ✅ Pre-COVID Peak
A8: 2020 | B8: ='📊 Raw Dataset'!N8 -> 4521 | C8: =B8-B7 -> -4400 | D8: =(B8-B7)/B7 -> -0.49321825 | E8: 🔴 Lockdown 1.0 — National shutdown Apr–May. Dine-in = ₹0
A9: 2021 | B9: ='📊 Raw Dataset'!N9 -> 4928 | C9: =B9-B8 -> 407 | D9: =(B9-B8)/B8 -> 0.090024331 | E9: 🔴 Delta 2nd Wave — Apr–May 2021 crash worse than 2020 in some states
A10: 2022 | B10: ='📊 Raw Dataset'!N10 -> 7545 | C10: =B10-B9 -> 2617 | D10: =(B10-B9)/B9 -> 0.53104708 | E10: 🟡 Omicron scare Jan 2022, gradual unlock H2. Near-recovery year
A11: 2023 | B11: ='📊 Raw Dataset'!N11 -> 10510 | C11: =B11-B10 -> 2965 | D11: =(B11-B10)/B10 -> 0.39297548 | E11: ✅ Full Recovery + Growth. Delivery-first boom.
A12: 2024 | B12: ='📊 Raw Dataset'!N12 -> 11410 | C12: =B12-B11 -> 900 | D12: =(B12-B11)/B11 -> 0.085632731 | E12: ✅ Premiumisation era. Tier 2 expansion.
A13: 2025 | B13: ='📊 Raw Dataset'!N13 -> 12375 | C13: =B13-B12 -> 965 | D13: =(B13-B12)/B12 -> 0.084574934 | E13: 🏆 Peak Year. Cloud kitchens + delivery maturity.
A15: Q3 — CAGR ANALYSIS: FULL PERIOD, PRE-COVID & POST-COVID RECOVERY
A16: Period | B16: Start Value (₹K) | C16: End Value (₹K) | D16: Years (n) | E16: CAGR % | F16: Interpretation
A17: Full Period CAGR (2018→2025) | B17: ='📊 Raw Dataset'!N6 -> 8260 | C17: ='📊 Raw Dataset'!N13 -> 12375 | D17: 7 | E17: =(C17/B17)^(1/D17)-1 -> 0.059450663 | F17: Blended rate — COVID years drag this down vs pre-COVID trajectory
A18: Pre-COVID CAGR (2018→2019) | B18: ='📊 Raw Dataset'!N6 -> 8260 | C18: ='📊 Raw Dataset'!N7 -> 8921 | D18: 1 | E18: =(C18/B18)^(1/D18)-1 -> 0.080024213 | F18: Strong organic growth before COVID disruption
A19: Post-COVID Recovery (2022→2025) | B19: ='📊 Raw Dataset'!N9 -> 4928 | C19: ='📊 Raw Dataset'!N13 -> 12375 | D19: 3 | E19: =(C19/B19)^(1/D19)-1 -> 0.35922547 | F19: Strong rebound — delivery-first + post-lockdown pent-up demand
A21: Q4 & Q5 — COVID DEPTH: LOCKDOWN 1.0 vs SECOND WAVE COMPARISON
A22: Period | B22: 2019 Sales (₹K) | C22: Impacted Year Sales (₹K) | D22: Absolute Drop (₹K) | E22: % Decline | F22: Context
A23: Apr–May 2020 vs 2019 (Lockdown 1.0) | B23: =SUM('📊 Raw Dataset'!E7:F7) -> 1339 | C23: =SUM('📊 Raw Dataset'!E8:F8) -> 215 | D23: =C23-B23 -> -1124 | E23: =(C23-B23)/B23 -> -0.83943241 | F23: Full national lockdown — dine-in banned, limited delivery
A24: Apr–May 2021 vs 2019 (2nd Wave) | B24: =SUM('📊 Raw Dataset'!E7:F7) -> 1339 | C24: =SUM('📊 Raw Dataset'!E9:F9) -> 240 | D24: =C24-B24 -> -1099 | E24: =(C24-B24)/B24 -> -0.82076176 | F24: Delta wave — state lockdowns (MH, DL, UP). Worse fear factor
A25: Full Year 2020 vs 2019 | B25: ='📊 Raw Dataset'!N7 -> 8921 | C25: ='📊 Raw Dataset'!N8 -> 4521 | D25: =C25-B25 -> -4400 | E25: =(C25-B25)/B25 -> -0.49321825 | F25: Full COVID year impact — largest annual decline
A26: Full Year 2021 vs 2019 | B26: ='📊 Raw Dataset'!N7 -> 8921 | C26: ='📊 Raw Dataset'!N9 -> 4928 | D26: =C26-B26 -> -3993 | E26: =(C26-B26)/B26 -> -0.44759556 | F26: 2nd wave year — still below 2019 despite partial recovery
A28: Q6 — RECOVERY RATE ANALYSIS
A29: Metric | B29: Value / Formula | C29: Interpretation
A30: 2019 Annual Total (Pre-COVID Benchmark) | B30: ='📊 Raw Dataset'!N7 -> 8921 | C30: Target benchmark for full recovery
A31: Lowest COVID Year Total (2020) | B31: ='📊 Raw Dataset'!N8 -> 4521 | C31: Trough of the pandemic crisis
A32: Trough Depth % below 2019 | B32: =(B31-B30)/B30 -> -0.49321825 | C32: How deeply sales fell at worst
A33: 2022 Annual Total | B33: ='📊 Raw Dataset'!N10 -> 7545 | C33: Near-recovery — Omicron year
A34: 2023 Annual Total (First Recovery Year) | B34: ='📊 Raw Dataset'!N11 -> 10510 | C34: First year to EXCEED 2019 levels ✅
A35: Years to Full Recovery | B35: =2023-2019 -> 4 | C35: 4 years from pre-COVID peak to full recovery
A37: Q8 — STANDARD DEVIATION (Monthly Sales Volatility per Year)
A38: Year | B38: Std Dev (₹K) | C38: Min Month (₹K) | D38: Max Month (₹K) | E38: Range (₹K) | F38: Volatility Assessment
A39: 2018 | B39: =STDEV('📊 Raw Dataset'!B6:M6) -> 126.04713 | C39: =MIN('📊 Raw Dataset'!B6:M6) -> 480 | D39: =MAX('📊 Raw Dataset'!B6:M6) -> 920 | E39: =D39-C39 -> 440 | F39: Low — Stable growth, no disruptions
A40: 2019 | B40: =STDEV('📊 Raw Dataset'!B7:M7) -> 136.21805 | C40: =MIN('📊 Raw Dataset'!B7:M7) -> 518 | D40: =MAX('📊 Raw Dataset'!B7:M7) -> 994 | E40: =D40-C40 -> 476 | F40: Low — Consistent pre-COVID performance
A41: 2020 | B41: =STDEV('📊 Raw Dataset'!B8:M8) -> 159.05581 | C41: =MIN('📊 Raw Dataset'!B8:M8) -> 95 | D41: =MAX('📊 Raw Dataset'!B8:M8) -> 558 | E41: =D41-C41 -> 463 | F41: VERY HIGH ⚡ — Lockdown 1.0 caused near-zero Apr–May vs normal other months
A42: 2021 | B42: =STDEV('📊 Raw Dataset'!B9:M9) -> 184.47436 | C42: =MIN('📊 Raw Dataset'!B9:M9) -> 110 | D42: =MAX('📊 Raw Dataset'!B9:M9) -> 710 | E42: =D42-C42 -> 600 | F42: VERY HIGH ⚡ — 2nd wave crash Apr–May again vs recovery in H2
A43: 2022 | B43: =STDEV('📊 Raw Dataset'!B10:M10) -> 180.20348 | C43: =MIN('📊 Raw Dataset'!B10:M10) -> 295 | D43: =MAX('📊 Raw Dataset'!B10:M10) -> 910 | E43: =D43-C43 -> 615 | F43: HIGH — Omicron Jan scare vs gradual H2 recovery. Wide range.
A44: 2023 | B44: =STDEV('📊 Raw Dataset'!B11:M11) -> 150.96407 | C44: =MIN('📊 Raw Dataset'!B11:M11) -> 630 | D44: =MAX('📊 Raw Dataset'!B11:M11) -> 1150 | E44: =D44-C44 -> 520 | F44: Moderate — Stable full recovery, less seasonal extremes
A45: 2024 | B45: =STDEV('📊 Raw Dataset'!B12:M12) -> 162.95333 | C45: =MIN('📊 Raw Dataset'!B12:M12) -> 690 | D45: =MAX('📊 Raw Dataset'!B12:M12) -> 1250 | E45: =D45-C45 -> 560 | F45: Low-Moderate — Consistent growth trend
...

Sheet 📋 Qualitative Analysis
A1: QUALITATIVE ANALYSIS — INDIA PIZZA MARKET (2018–2025) | COVID-19 IMPACT EDITION
A2: Comprehensive Business Intelligence Report accounting for National Lockdown 1.0 (2020), Delta Second Wave (2021), Omicron (2022), and Post-COVID Recovery Boom (2023–2025)
A4: 1. OVERALL TREND ANALYSIS — THE FULL PICTURE
A5: 📈 PRE-COVID GROWTH (2018–2019): The India pizza market was on a healthy upward trajectory — Annual sales grew from ₹7,990K (2018) to approximately ₹8,721K (2019), a ~9% YoY growth. This growth was driven by increasing urbanisation, rising youth population, expansion of delivery aggregators like Swiggy and Zomato, and rapid growth of organised QSR chains like Domino's, Pizza Hut, and emerging local brands.
A6: 🔴 LOCKDOWN 1.0 — CATASTROPHIC COLLAPSE (Apr–May 2020): India's National Lockdown 1.0 (announced March 24, 2020) caused the single most devastating crash in this dataset. April 2020 recorded just ₹95K — a 86% collapse from April 2019 (₹637K). May 2020 was ₹120K versus ₹702K in May 2019 — an 83% drop. Dine-in restaurants were completely shut. Only limited home delivery was permitted, and consumer fear, reduced income, and delivery infrastructure disruptions further suppressed even that channel.
A7: 🟡 UNLOCK 1.0 AND GRADUAL RESTART (Jun–Dec 2020): As India began 'Unlock 1.0' in June 2020, sales began recovering but remained severely depressed. June 2020 saw ₹195K — roughly 25% of June 2019. By December 2020, sales had climbed to ₹520K — approximately 52% of December 2019's ₹994K. The H2 2020 recovery was driven by delivery normalisation and Diwali/festive season demand, but dine-in remained restricted throughout.
A8: 🔴 SECOND WAVE — DELTA VARIANT DOUBLES DOWN (Apr–May 2021): Just as recovery was beginning, India's devastating Delta Second Wave (April–May 2021) struck. Maharashtra, Delhi, Uttar Pradesh and other key pizza markets re-imposed state-level lockdowns. April 2021 collapsed to ₹110K and May 2021 to ₹130K — comparable to or slightly worse than Lockdown 1.0 figures in absolute terms, and MORE damaging because businesses had already depleted their reserves during 2020.
A9: 🟢 GRADUAL NORMALISATION (H2 2021 – 2022): The second half of 2021 saw a meaningful improvement — October to December 2021 (₹580K–₹710K) showed the festive season bringing consumers back. However, 2022 began cautiously with Omicron (January 2022: ₹295K — lowest non-lockdown figure) before a steady recovery through the year. By December 2022 (₹910K), sales were approaching but still below December 2019 levels.
A10: 🚀 FULL RECOVERY AND BOOM (2023–2025): The year 2023 marked true recovery — Annual Total crossed and exceeded 2019 levels for the first time. This was driven by: (a) normalised dine-in, (b) permanently elevated food delivery adoption post-COVID, (c) expansion into Tier 2 cities, and (d) new post-pandemic consumer habits. 2024–2025 represent a new growth era with CAGR of 15–18% from the 2022 base.
A12: 2. COVID-19 IMPACT — INDIA-SPECIFIC ANALYSIS
A13: 🏙️ WHY INDIA WAS PARTICULARLY AFFECTED: India's pizza market is concentrated in metro and Tier 1 cities (Mumbai, Delhi, Bengaluru, Hyderabad, Chennai, Kolkata). These cities were also the epicentres of both COVID waves — meaning the most pizza-consuming population was hit hardest and longest. Additionally, India had one of the strictest lockdown regimes globally in April–May 2020, with near-total restrictions on movement and economic activity.
A14: 🚗 DELIVERY MODEL GAPS IN 2020: Unlike Western markets where food delivery infrastructure was already mature, Indian delivery networks in 2020 were partially constrained by: (a) containment zones blocking delivery personnel, (b) consumer fear of food safety, (c) supply chain disruptions for ingredients. This meant even the delivery channel could not compensate for dine-in loss — explaining why Apr–May 2020 figures are as low as ₹95–120K.
... A37: 🌟 OPPORTUNITY 3 — PREDICTABLE SEASONAL WINDOWS: The 8 years of data create a highly reliable demand calendar. Businesses that use this data to pre-plan marketing campaigns (January deal combos to fight the seasonal slump, December party packages, July school-holiday family deals) can capture additional 10–15% revenue from moments that competitors miss through reactive rather than planned marketing.

Sheet 🎯 Marking Scheme
A1: MARKING SCHEME & EVALUATION RUBRIC — COVID-AWARE ASSESSMENT
A3: Q No. | B3: Topic | C3: Max Marks | D3: Full Credit Criteria | E3: Partial Credit | F3: Zero Credit
A4: Q1 | B4: MoM % Change + extremes | C4: 8 | D4: All MoM values via formula; Apr 2020 correctly identified as lowest; 2021 H2 as largest recovery | E4: Correct formula, misses extremes identification | F4: Hardcoded or wrong formula
A5: Q2 | B5: YoY Growth + COVID years | C5: 8 | D5: Negative growth correctly shown for 2020 & 2021; 2023 identified as first recovery year; formula-driven | E5: 5+ years correct, COVID context missing | F5: No COVID distinction
A6: Q3 | B6: CAGR — 3 periods | C6: 7 | D6: All 3 CAGR correctly computed; post-COVID > pre-COVID rate explained (delivery boom effect) | E6: 2 of 3 CAGRs correct | F6: Self-referencing formula or hardcoded
A7: Q4 | B7: Lockdown 1.0 Depth | C7: 7 | D7: Apr–May 2020 vs 2019 drop calculated; ~85% decline identified; estimated loss computed via formula | E7: Drop % correct, estimated loss missing | F7: Wrong year reference or hardcoded
A8: Q5 | B8: 2nd Wave vs 1st Wave | C8: 6 | D8: Comparison shows similar magnitude; explains 2nd wave MORE damaging financially due to depleted reserves | E8: Numbers correct, financial context missing | F8: Compares wrong months or years
A9: Q6 | B9: Recovery Rate | C9: 5 | D9: Recovery year = 2023 identified; trough depth % correct; 4 years to recovery noted | E9: 2 of 3 metrics correct | F9: Wrong recovery year (e.g., says 2022)
A10: Q7 | B10: Seasonal Index — clean vs raw | C10: 6 | D10: Both clean (excl 2020–21) and raw seasonal index computed; correctly notes COVID distortion in raw | E10: One of two indices computed correctly | F10: No acknowledgement of COVID distortion
A11: Q8 | B11: Std Dev — volatility | C11: 5 | D11: STDEV() for all years; 2020 & 2021 highest correctly explained (lockdown month extremes vs normal months) | E11: STDEV correct, explanation missing | F11: Hardcoded or wrong function
A12: Q9 | B12: Year Share % + revenue loss | C12: 5 | D12: Share % sums to 100%; COVID years noted as undersized; estimated lost revenue vs projected growth computed | E12: Share % correct, loss estimation missing | F12: Doesn't sum to 100%
A13: Q10 | B13: 3-Month Moving Average | C13: 3 | D13: Correct rolling 3-month formula; Apr–Jun 2020 as steepest drop correctly identified | E13: Formula correct, identification missing | F13: Wrong window
A14: Q11 | B14: Line Chart — COVID highlighted | C14: 7 | D14: Chart present; 2020 & 2021 in RED; annotation on V-recovery; title and axis labels | E14: Chart present, missing COVID highlighting or annotation | F14: No chart or wrong data range
A15: Q12 | B15: H1 vs H2 Bar Chart | C15: 6 | D15: H1/H2 split correct for all years; chart clearly shows 2020–21 H1 devastation vs H2 partial recovery | E15: Chart present, some H1/H2 errors | F15: No chart
... A20: Q17 | B20: Risk & Opportunity — written | C20: 4 | D20: 3 risks + 3 opportunities; all tied to specific months/years; includes pandemic recurrence risk | E20: 4 of 6 with data | F20: Generic list, no data
